<?xml version="1.0" ?>
<robot xmlns:xacro="http://ros.org/wiki/xacro">
	<xacro:macro name="torso" params="name prefix">
		<!-- link list -->
		<link name="base_link">
			<visual>
				<geometry>
					<mesh filename="package://motoman_sda5f_support/meshes/visual/base_link.dae" />
				</geometry>
				<material name="blue">
					<color rgba="0 0 1 1"/>
				</material>
			</visual>
			<collision>
				<geometry>
					<mesh filename="package://motoman_sda5f_support/meshes/collision/base_link.stl" />
				</geometry>
				<material name="yellow">
					<color rgba="0 1 1 1"/>
				</material>
			</collision>
		</link>
		<link name="frame_lower_link">
			<visual>
				<geometry>
					<mesh filename="package://motoman_sda5f_support/meshes/visual/lower_part.stl" />
				</geometry>
				<material name="silver">
					<color rgba="0.8 0.8 0.8 1"/>
				</material>
			</visual>
			<collision>
				<geometry>
					<mesh filename="package://motoman_sda5f_support/meshes/collision/lower_part.stl" />
				</geometry>
				<material name="silver">
					<color rgba="0.8 0.8 0.8 1"/>
				</material>
			</collision>
		</link>
		<link name="frame_upper_link">
			<visual>
				<geometry>
					<mesh filename="package://motoman_sda5f_support/meshes/visual/upper_part.stl" />
				</geometry>
				<material name="silver">
					<color rgba="0.8 0.8 0.8 1"/>
				</material>
			</visual>
			<collision>
				<geometry>
					<mesh filename="package://motoman_sda5f_support/meshes/collision/upper_part.stl" />
				</geometry>
				<material name="silver">
					<color rgba="0.8 0.8 0.8 1"/>
				</material>
			</collision>
		</link>
		<link name="${prefix}link_b1">
			<visual>
				<origin rpy="0 0 0" xyz="0 0 0"/>
				<geometry>
					<mesh filename="package://motoman_sda5f_support/meshes/visual/torso_link.dae"/>
				</geometry>
				<material name="silver">
					<color rgba="0.8 0.8 0.8 1"/>
				</material>
			</visual>
			<collision>
				<origin rpy="0 0 0" xyz="0 0 0"/>
				<geometry>
					<mesh filename="package://motoman_sda5f_support/meshes/collision/torso_link.stl" />
				</geometry>
				<material name="yellow"/>
			</collision>
		</link>
		<link name="${prefix}link_b2">
			<visual>
				<origin rpy="0 0 0" xyz="0 0 0"/>
				<geometry>
					<mesh filename="package://motoman_sda5f_support/meshes/visual/torso_link.stl"/>
				</geometry>
				<material name="silver">
					<color rgba="0.8 0.8 0.8 1"/>
				</material>
			</visual>
			<collision>
				<origin rpy="0 0 0" xyz="0 0 0"/>
				<geometry>
					<mesh filename="package://motoman_sda5f_support/meshes/collision/torso_link.stl" />
				</geometry>
				<material name="yellow"/>
			</collision>
		</link>
		<!-- joint list -->
		<joint name="frame_upper" type="fixed">
			<parent link="base_link"/>
			<child link="frame_upper_link"/>
			<origin xyz="0.15 0. -0.36" rpy="0 0 1.5708"/>
		</joint>
		<joint name="frame_lower" type="fixed">
			<parent link="base_link"/>
			<child link="frame_lower_link"/>
			<origin xyz="0.15 0. -0.36" rpy="0 0 1.5708"/>
		</joint>
		<joint name="${prefix}joint_b1" type="revolute">
			<parent link="base_link"/>
			<child link="${prefix}link_b1"/>
			<origin xyz="0.045 0 0.7296" rpy="0 0 0"/>
			<axis xyz="0 0 1" />
			<limit lower="-2.9570" upper="2.9570" effort="100" velocity="3.14" />
		</joint>
		<joint name="${prefix}joint_b2" type="revolute">
			<parent link="base_link"/>
			<child link="${prefix}link_b2"/>
			<origin xyz="0.045 0 0.7296" rpy="0 0 0"/>
			<axis xyz="0 0 1" />
			<limit lower="-2.9570" upper="2.9570" effort="100" velocity="3.14" />
			<mimic joint="${prefix}joint_b1" multiplier="1" offset="0"/>
		</joint>
		<!-- end of joint list -->
	</xacro:macro>
</robot>
